<?xml version="1.0" ?>
<!-- =================================================================================== -->
<!-- |    This document was autogenerated by xacro from src/arx_urdf/arx_x7_description/model/xacro/x7.xacro | -->
<!-- |    EDITING THIS FILE BY HAND IS NOT RECOMMENDED                                 | -->
<!-- =================================================================================== -->
<robot name="00-X7aaz">
  <material name="silver">
    <color rgba="0.700 0.700 0.700 1.000"/>
  </material>
  
  <!-- New root link for world coordinate frame -->
  <link name="base_link"/>
  <link name="base_link_x"/>
  <link name="base_link_y"/>
  <link name="base_link_z"/>
  

  <joint name="base_x" type="prismatic">
    <origin rpy="0 0 0.0" xyz="0 0 0.0"/>
    <parent link="base_link"/>
    <child link="base_link_x"/>
    <axis xyz="1 0 0"/>
    <dynamics damping="10.0"/>
    <limit effort="87" lower="-5.0" upper="5.0" velocity="100.0"/>
  </joint>

<joint name="base_y" type="prismatic">
    <origin rpy="0 0 0.0" xyz="0 0 0.0"/>
    <parent link="base_link_x"/>
    <child link="base_link_y"/>
    <axis xyz="0 1 0"/>
    <dynamics damping="10.0"/>
    <limit effort="87" lower="-5.0" upper="5.0" velocity="100.0"/>
  </joint>

<joint name="base_z" type="revolute">
    <origin rpy="0 0 0.0" xyz="0 0 0.0"/>
    <parent link="base_link_y"/>
    <child link="base_link_z"/>
    <axis xyz="0 0 1"/>
    <dynamics damping="10.0"/>
    <limit effort="87" lower="-6.0" upper="6.0" velocity="100.0"/>
  </joint>

  <!-- Joint to rotate entire robot 180 degrees around x-axis -->
  <joint name="base_link_z_to_base_link0" type="fixed">
    <origin rpy="3.1415926 0 0" xyz="0 0 0"/>
    <parent link="base_link_z"/>
    <child link="base_link0"/>
  </joint>


  
  <link name="base_link0">
    <inertial>
      <origin rpy="0 0 0" xyz="-0.02788627568581226 -0.031293293601240654 -0.2137244378001211"/>
      <mass value="68.02485174331227"/>
      <inertia ixx="7.896909" ixy="0.008791" ixz="0.078962" iyy="8.057484" iyz="0.13147" izz="2.250946"/>
    </inertial>
    <visual>
      <origin rpy="3.5299186013195283e-15 1.5233538593592258e-29 -3.658014792536898e-15" xyz="-0.015256844136058456 -0.1573132267869905 0.09318884834810495"/>
      <geometry>
        <mesh filename="./meshes/base_link.stl" scale="0.001 0.001 0.001"/>
      </geometry>
      <material name="silver"/>
    </visual>
    <collision>
      <origin rpy="3.5299186013195283e-15 1.5233538593592258e-29 -3.658014792536898e-15" xyz="-0.015256844136058456 -0.1573132267869905 0.09318884834810495"/>
      <geometry>
        <mesh filename="./meshes/base_link.stl" scale="0.001 0.001 0.001"/>
      </geometry>
    </collision>
  </link>
  <link name="body_link2_1">
    <inertial>
      <origin rpy="0 0 0" xyz="0.05424383454957651 -0.06956807233610031 -0.48433314722625964"/>
      <mass value="24.603257212325776"/>
      <inertia ixx="0.156979" ixy="0.001689" ixz="0.016462" iyy="0.478969" iyz="-5.2e-05" izz="0.578528"/>
    </inertial>
    <visual>
      <origin rpy="3.5299186013195283e-15 1.5233538593592258e-29 -3.658014792536898e-15" xyz="-0.009171844136311141 -0.19232122678699098 0.323403945243197"/>
      <geometry>
        <mesh filename="./meshes/body_link2.stl" scale="0.001 0.001 0.001"/>
      </geometry>
      <material name="silver"/>
    </visual>
    <collision>
      <origin rpy="3.5299186013195283e-15 1.5233538593592258e-29 -3.658014792536898e-15" xyz="-0.009171844136311141 -0.19232122678699098 0.323403945243197"/>
      <geometry>
        <mesh filename="./meshes/body_link2.stl" scale="0.001 0.001 0.001"/>
      </geometry>
    </collision>
  </link>
  <link name="head_link1_1">
    <inertial>
      <origin rpy="0 0 0" xyz="3.2551294518179397e-07 -0.00038379909113506194 -0.04083809461872978"/>
      <mass value="1.1685832509612815"/>
      <inertia ixx="0.000744" ixy="-0.0" ixz="0.0" iyy="0.000728" iyz="2.6e-05" izz="0.000505"/>
    </inertial>
    <visual>
      <origin rpy="4.009121523980654e-15 1.6416829951423782e-29 -3.658014792536899e-15" xyz="-0.18967184413630755 -0.122540226786993 0.8525419264502125"/>
      <geometry>
        <mesh filename="./meshes/head_link1.stl" scale="0.001 0.001 0.001"/>
      </geometry>
      <material name="silver"/>
    </visual>
    <collision>
      <origin rpy="4.009121523980654e-15 1.6416829951423782e-29 -3.658014792536899e-15" xyz="-0.18967184413630755 -0.122540226786993 0.8525419264502125"/>
      <geometry>
        <mesh filename="./meshes/head_link1.stl" scale="0.001 0.001 0.001"/>
      </geometry>
    </collision>
  </link>
  <link name="head_link2_1">
    <inertial>
      <origin rpy="0 0 0" xyz="0.008891517012994815 -0.02138240004232105 -0.07362536398787023"/>
      <mass value="1.7036703045112362"/>
      <inertia ixx="0.006557" ixy="-5.7e-05" ixz="0.000471" iyy="0.005513" iyz="-0.000316" izz="0.008156"/>
    </inertial>
    <visual>
      <origin rpy="4.009121523980634e-15 -2.8679594705812487e-16 -3.6580147925368966e-15" xyz="-0.18967184413619376 -0.14754022678699194 0.9015419264501422"/>
      <geometry>
        <mesh filename="./meshes/head_link2.stl" scale="0.001 0.001 0.001"/>
      </geometry>
      <material name="silver"/>
    </visual>
    <collision>
      <origin rpy="4.009121523980634e-15 -2.8679594705812487e-16 -3.6580147925368966e-15" xyz="-0.18967184413619376 -0.14754022678699194 0.9015419264501422"/>
      <geometry>
        <mesh filename="./meshes/head_link2.stl" scale="0.001 0.001 0.001"/>
      </geometry>
    </collision>
  </link>
  <link name="arm_r_link1_1">
    <inertial>
      <origin rpy="0 0 0" xyz="0.022412358358475548 0.024326137468245163 -1.5165199018785103e-07"/>
      <mass value="0.37634949195895756"/>
      <inertia ixx="0.000339" ixy="-9.1e-05" ixz="-0.0" iyy="0.000241" iyz="-0.0" izz="0.00038"/>
    </inertial>
    <visual>
      <origin rpy="3.5299186013195283e-15 1.5233538593592258e-29 -3.658014792536898e-15" xyz="-0.2559596201375548 -0.39320934163869536 1.02378595447682"/>
      <geometry>
        <mesh filename="./meshes/arm_r_link1.stl" scale="0.001 0.001 0.001"/>
      </geometry>
      <material name="silver"/>
    </visual>
    <collision>
      <origin rpy="3.5299186013195283e-15 1.5233538593592258e-29 -3.658014792536898e-15" xyz="-0.2559596201375548 -0.39320934163869536 1.02378595447682"/>
      <geometry>
        <mesh filename="./meshes/arm_r_link1.stl" scale="0.001 0.001 0.001"/>
      </geometry>
    </collision>
  </link>
  <link name="arm_r_link2_1">
    <inertial>
      <origin rpy="0 0 0" xyz="-0.023480503352369397 0.005705988652512234 0.023495564095083576"/>
      <mass value="3.0700063054295343"/>
      <inertia ixx="0.005141" ixy="-0.00012" ixz="0.000234" iyy="0.005172" iyz="0.000119" izz="0.003088"/>
    </inertial>
    <visual>
      <origin rpy="2.0013386882728807e-15 1.5435735845241277e-29 -3.7690370949994146e-15" xyz="-0.21692184413630944 -0.3243212267869908 0.8074039452431967"/>
      <geometry>
        <mesh filename="./meshes/arm_r_link2.stl" scale="0.001 0.001 0.001"/>
      </geometry>
      <material name="silver"/>
    </visual>
    <collision>
      <origin rpy="2.0013386882728807e-15 1.5435735845241277e-29 -3.7690370949994146e-15" xyz="-0.21692184413630944 -0.3243212267869908 0.8074039452431967"/>
      <geometry>
        <mesh filename="./meshes/arm_r_link2.stl" scale="0.001 0.001 0.001"/>
      </geometry>
    </collision>
  </link>
  <link name="arm_r_link3_1">
    <inertial>
      <origin rpy="0 0 0" xyz="-0.0019947308643903927 -0.0006814522943049683 0.1368879719819266"/>
      <mass value="2.981863793105914"/>
      <inertia ixx="0.019419" ixy="-2.1e-05" ixz="0.00032" iyy="0.019484" iyz="0.000201" izz="0.003344"/>
    </inertial>
    <visual>
      <origin rpy="5.3223655638150194e-15 2.2204460492503312e-15 -3.769037094999406e-15" xyz="-0.18967184413630786 -0.3243212267869912 0.7209039452431967"/>
      <geometry>
        <mesh filename="./meshes/arm_r_link3.stl" scale="0.001 0.001 0.001"/>
      </geometry>
      <material name="silver"/>
    </visual>
    <collision>
      <origin rpy="5.3223655638150194e-15 2.2204460492503312e-15 -3.769037094999406e-15" xyz="-0.18967184413630786 -0.3243212267869912 0.7209039452431967"/>
      <geometry>
        <mesh filename="./meshes/arm_r_link3.stl" scale="0.001 0.001 0.001"/>
      </geometry>
    </collision>
  </link>
  <link name="arm_r_link4_1">
    <inertial>
      <origin rpy="0 0 0" xyz="0.06071898868694006 0.025423510668492383 6.854336575257136e-05"/>
      <mass value="1.3116533194741544"/>
      <inertia ixx="0.001041" ixy="-1.2e-05" ixz="-3e-06" iyy="0.001167" iyz="-0.0" izz="0.001616"/>
    </inertial>
    <visual>
      <origin rpy="5.322365563815022e-15 3.0767443469122387e-15 -1.1045018358990257e-15" xyz="-0.19049604503707818 -0.29517659560118414 0.5057543340961231"/>
      <geometry>
        <mesh filename="./meshes/arm_r_link4.stl" scale="0.001 0.001 0.001"/>
      </geometry>
      <material name="silver"/>
    </visual>
    <collision>
      <origin rpy="5.322365563815022e-15 3.0767443469122387e-15 -1.1045018358990257e-15" xyz="-0.19049604503707818 -0.29517659560118414 0.5057543340961231"/>
      <geometry>
        <mesh filename="./meshes/arm_r_link4.stl" scale="0.001 0.001 0.001"/>
      </geometry>
    </collision>
  </link>
  <link name="arm_r_link5_1">
    <inertial>
      <origin rpy="0 0 0" xyz="0.08339346922205759 -0.000980944991483601 -3.569533188296781e-05"/>
      <mass value="1.3925397947387612"/>
      <inertia ixx="0.000669" ixy="2.2e-05" ixz="-3e-06" iyy="0.001508" iyz="-2e-06" izz="0.001551"/>
    </inertial>
    <visual>
      <origin rpy="5.981285467309888e-15 3.076744346912257e-15 -6.933172715181096e-15" xyz="-0.2831718441363083 -0.3243212267869934 0.5044039452432006"/>
      <geometry>
        <mesh filename="./meshes/arm_r_link5.stl" scale="0.001 0.001 0.001"/>
      </geometry>
      <material name="silver"/>
    </visual>
    <collision>
      <origin rpy="5.981285467309888e-15 3.076744346912257e-15 -6.933172715181096e-15" xyz="-0.2831718441363083 -0.3243212267869934 0.5044039452432006"/>
      <geometry>
        <mesh filename="./meshes/arm_r_link5.stl" scale="0.001 0.001 0.001"/>
      </geometry>
    </collision>
  </link>
  <link name="arm_r_link6_1">
    <inertial>
      <origin rpy="0 0 0" xyz="0.056354003284026954 0.026892753329476937 -0.0015318308576494633"/>
      <mass value="1.192468848199776"/>
      <inertia ixx="0.000735" ixy="-3.4e-05" ixz="-4.5e-05" iyy="0.00096" iyz="1e-06" izz="0.001201"/>
    </inertial>
    <visual>
      <origin rpy="5.981285467309855e-15 6.875282229046669e-15 -3.491481338843086e-15" xyz="-0.378671844136308 -0.29707122678699516 0.5044039452432009"/>
      <geometry>
        <mesh filename="./meshes/arm_r_link6.stl" scale="0.001 0.001 0.001"/>
      </geometry>
      <material name="silver"/>
    </visual>
    <collision>
      <origin rpy="5.981285467309855e-15 6.875282229046669e-15 -3.491481338843086e-15" xyz="-0.378671844136308 -0.29707122678699516 0.5044039452432009"/>
      <geometry>
        <mesh filename="./meshes/arm_r_link6.stl" scale="0.001 0.001 0.001"/>
      </geometry>
    </collision>
  </link>
  <link name="arm_r_link7_1">
    <inertial>
      <origin rpy="0 0 0" xyz="0.07446127977197714 -8.750794004427909e-05 -0.020217378023051347"/>
      <mass value="1.238313218461711"/>
      <inertia ixx="0.00087" ixy="3e-06" ixz="0.000152" iyy="0.001078" iyz="5e-06" izz="0.001374"/>
    </inertial>
    <visual>
      <origin rpy="6.102756063125741e-15 -1.6653345369375926e-16 -3.4914813388431282e-15" xyz="-0.44467184413630756 -0.3243212267869946 0.4824039452432018"/>
      <geometry>
        <mesh filename="./meshes/arm_r_link7.stl" scale="0.001 0.001 0.001"/>
      </geometry>
      <material name="silver"/>
    </visual>
    <collision>
      <origin rpy="6.102756063125741e-15 -1.6653345369375926e-16 -3.4914813388431282e-15" xyz="-0.44467184413630756 -0.3243212267869946 0.4824039452432018"/>
      <geometry>
        <mesh filename="./meshes/arm_r_link7.stl" scale="0.001 0.001 0.001"/>
      </geometry>
    </collision>
  </link>
  <link name="arm_l_link1_1">
    <inertial>
      <origin rpy="0 0 0" xyz="0.022412358358537027 -0.02432567247619527 -1.5165202593703242e-07"/>
      <mass value="0.3763494919589559"/>
      <inertia ixx="0.000339" ixy="9.1e-05" ixz="-0.0" iyy="0.000241" iyz="0.0" izz="0.00038"/>
    </inertial>
    <visual>
      <origin rpy="-3.1415926535897896 3.993674239980411e-16 -3.3249478851493492e-15" xyz="-0.2559596201374901 0.3932098066307419 1.0237859544767858"/>
      <geometry>
        <mesh filename="./meshes/arm_l_link1.stl" scale="0.001 0.001 0.001"/>
      </geometry>
      <material name="silver"/>
    </visual>
    <collision>
      <origin rpy="-3.1415926535897896 3.993674239980411e-16 -3.3249478851493492e-15" xyz="-0.2559596201374901 0.3932098066307419 1.0237859544767858"/>
      <geometry>
        <mesh filename="./meshes/arm_l_link1.stl" scale="0.001 0.001 0.001"/>
      </geometry>
    </collision>
  </link>
  <link name="arm_l_link2_1">
    <inertial>
      <origin rpy="0 0 0" xyz="-0.023480503352307003 -0.00570552366046273 0.02349556417614007"/>
      <mass value="3.0700063054295326"/>
      <inertia ixx="0.005141" ixy="0.00012" ixz="0.000234" iyy="0.005172" iyz="-0.000119" izz="0.003088"/>
    </inertial>
    <visual>
      <origin rpy="-3.1415926535897873 3.993674239980373e-16 -2.8253475240680284e-15" xyz="-0.21692184413624516 0.32432169177903564 0.807403945243161"/>
      <geometry>
        <mesh filename="./meshes/arm_l_link2.stl" scale="0.001 0.001 0.001"/>
      </geometry>
      <material name="silver"/>
    </visual>
    <collision>
      <origin rpy="-3.1415926535897873 3.993674239980373e-16 -2.8253475240680284e-15" xyz="-0.21692184413624516 0.32432169177903564 0.807403945243161"/>
      <geometry>
        <mesh filename="./meshes/arm_l_link2.stl" scale="0.001 0.001 0.001"/>
      </geometry>
    </collision>
  </link>
  <link name="arm_l_link3_1">
    <inertial>
      <origin rpy="0 0 0" xyz="-0.0019947278011221703 0.0006819209913284108 0.13688794355607903"/>
      <mass value="2.9818626930617"/>
      <inertia ixx="0.019419" ixy="2.1e-05" ixz="0.00032" iyy="0.019484" iyz="-0.000201" izz="0.003344"/>
    </inertial>
    <visual>
      <origin rpy="-3.141592653589792 2.886579864025421e-15 -2.8253475240680225e-15" xyz="-0.18967184413624447 0.3243216917790366 0.720903945243162"/>
      <geometry>
        <mesh filename="./meshes/arm_l_link3.stl" scale="0.001 0.001 0.001"/>
      </geometry>
      <material name="silver"/>
    </visual>
    <collision>
      <origin rpy="-3.141592653589792 2.886579864025421e-15 -2.8253475240680225e-15" xyz="-0.18967184413624447 0.3243216917790366 0.720903945243162"/>
      <geometry>
        <mesh filename="./meshes/arm_l_link3.stl" scale="0.001 0.001 0.001"/>
      </geometry>
    </collision>
  </link>
  <link name="arm_l_link4_1">
    <inertial>
      <origin rpy="0 0 0" xyz="0.06071898868700076 -0.025423045676445905 6.854336571421316e-05"/>
      <mass value="1.3116533194741542"/>
      <inertia ixx="0.001041" ixy="1.2e-05" ixz="-3e-06" iyy="0.001167" iyz="0.0" izz="0.001616"/>
    </inertial>
    <visual>
      <origin rpy="-3.141592653589792 2.984115399562549e-15 -5.767438539324695e-15" xyz="-0.19049604503701328 0.2951770605932289 0.5057543340960878"/>
      <geometry>
        <mesh filename="./meshes/arm_l_link4.stl" scale="0.001 0.001 0.001"/>
      </geometry>
      <material name="silver"/>
    </visual>
    <collision>
      <origin rpy="-3.141592653589792 2.984115399562549e-15 -5.767438539324695e-15" xyz="-0.19049604503701328 0.2951770605932289 0.5057543340960878"/>
      <geometry>
        <mesh filename="./meshes/arm_l_link4.stl" scale="0.001 0.001 0.001"/>
      </geometry>
    </collision>
  </link>
  <link name="arm_l_link5_1">
    <inertial>
      <origin rpy="0 0 0" xyz="0.08339346922211793 0.0009814099835294132 -3.5695331919993745e-05"/>
      <mass value="1.392539794738761"/>
      <inertia ixx="0.000669" ixy="-2.2e-05" ixz="-3e-06" iyy="0.001508" iyz="2e-06" izz="0.001551"/>
    </inertial>
    <visual>
      <origin rpy="-3.141592653589792 2.9841153995625207e-15 6.123233995738446e-17" xyz="-0.2831718441362437 0.3243216917790372 0.5044039452431649"/>
      <geometry>
        <mesh filename="./meshes/arm_l_link5.stl" scale="0.001 0.001 0.001"/>
      </geometry>
      <material name="silver"/>
    </visual>
    <collision>
      <origin rpy="-3.141592653589792 2.9841153995625207e-15 6.123233995738446e-17" xyz="-0.2831718441362437 0.3243216917790372 0.5044039452431649"/>
      <geometry>
        <mesh filename="./meshes/arm_l_link5.stl" scale="0.001 0.001 0.001"/>
      </geometry>
    </collision>  
  </link>
  <link name="arm_l_link6_1">
    <inertial>
      <origin rpy="0 0 0" xyz="0.056354003284060594 -0.026892288120110075 -0.0015318308576687256"/>
      <mass value="1.1924688481985686"/>
      <inertia ixx="0.000735" ixy="3.4e-05" ixz="-4.5e-05" iyy="0.00096" iyz="-1e-06" izz="0.001201"/>
    </inertial>
    <visual>
      <origin rpy="-3.1415926535897896 7.513660468206103e-15 6.123233995739475e-17" xyz="-0.3786718441362456 0.29707169177903814 0.5044039452431677"/>
      <geometry>
        <mesh filename="./meshes/arm_l_link6.stl" scale="0.001 0.001 0.001"/>
      </geometry>
      <material name="silver"/>
    </visual>
    <collision>
      <origin rpy="-3.1415926535897896 7.513660468206103e-15 6.123233995739475e-17" xyz="-0.3786718441362456 0.29707169177903814 0.5044039452431677"/>
      <geometry>
        <mesh filename="./meshes/arm_l_link6.stl" scale="0.001 0.001 0.001"/>
      </geometry>
    </collision>
  </link>
  <link name="arm_l_link7_1">
    <inertial>
      <origin rpy="0 0 0" xyz="0.07446127977687811 8.795383301993254e-05 -0.020217378023171473"/>
      <mass value="1.2383132186826822"/>
      <inertia ixx="0.00087" ixy="-3e-06" ixz="0.000152" iyy="0.001078" iyz="-5e-06" izz="0.001374"/>
    </inertial>
    <visual>
      <origin rpy="-3.1415926535897913 -1.9428902930939843e-16 6.12323399573745e-17" xyz="-0.44467184413624505 0.32432169177903625 0.482403945243167"/>
      <geometry>
        <mesh filename="./meshes/arm_l_link7.stl" scale="0.001 0.001 0.001"/>
      </geometry>
      <material name="silver"/>
    </visual>
    <collision>
      <origin rpy="-3.1415926535897913 -1.9428902930939843e-16 6.12323399573745e-17" xyz="-0.44467184413624505 0.32432169177903625 0.482403945243167"/>
      <geometry>
        <mesh filename="./meshes/arm_l_link7.stl" scale="0.001 0.001 0.001"/>
      </geometry>
    </collision>
  </link>
  <link name="wheel_2">
    <inertial>
      <origin rpy="0 0 0" xyz="0.0013051432894030657 0.0022591910259763814 -4.439392070759718e-07"/>
      <mass value="4.248031072877931"/>
      <inertia ixx="0.008031" ixy="0.002428" ixz="0.0" iyy="0.010834" iyz="-0.0" izz="0.006629"/>
    </inertial>
    <visual>
      <origin rpy="0 0 0" xyz="-0.175463 -0.280847 0.026811"/>
      <geometry>
        <mesh filename="./meshes/wheel_2.stl" scale="0.001 0.001 0.001"/>
      </geometry>
      <material name="silver"/>
    </visual>
    <collision>
      <origin rpy="0 0 0" xyz="-0.175463 -0.280847 0.026811"/>
      <geometry>
        <mesh filename="./meshes/wheel_2.stl" scale="0.001 0.001 0.001"/>
      </geometry>
    </collision>
  </link>
  <link name="wheel_1">
    <inertial>
      <origin rpy="0 0 0" xyz="-0.002608882124192413 3.476519027864611e-07 -4.439392085470173e-07"/>
      <mass value="4.248031072877931"/>
      <inertia ixx="0.012235" ixy="0.0" ixz="0.0" iyy="0.006629" iyz="0.0" izz="0.006629"/>
    </inertial>
    <visual>
      <origin rpy="0 0 0" xyz="0.371585 0.034992 0.026811"/>
      <geometry>
        <mesh filename="./meshes/wheel_1.stl" scale="0.001 0.001 0.001"/>
      </geometry>
      <material name="silver"/>
    </visual>
    <collision>
      <origin rpy="0 0 0" xyz="0.371585 0.034992 0.026811"/>
      <geometry>
        <mesh filename="./meshes/wheel_1.stl" scale="0.001 0.001 0.001"/>
      </geometry>
    </collision>
  </link>
  <link name="wheel_3">
    <inertial>
      <origin rpy="0 0 0" xyz="0.0013049438335925867 -0.002259841189761247 -4.4393920997642944e-07"/>
      <mass value="4.248031072877931"/>
      <inertia ixx="0.008031" ixy="-0.002428" ixz="-0.0" iyy="0.010834" iyz="-0.0" izz="0.006629"/>
    </inertial>
    <visual>
      <origin rpy="0 0 0" xyz="-0.175463 0.35083 0.026811"/>
      <geometry>
        <mesh filename="./meshes/wheel_3.stl" scale="0.001 0.001 0.001"/>
      </geometry>
      <material name="silver"/>
    </visual>
    <collision>
      <origin rpy="0 0 0" xyz="-0.175463 0.35083 0.026811"/>
      <geometry>
        <mesh filename="./meshes/wheel_3.stl" scale="0.001 0.001 0.001"/>
      </geometry>
    </collision>
  </link>
  <link name="catch_1_1">
    <inertial>
      <origin rpy="0 0 0" xyz="0.016354221810850333 -0.06789088940201943 0.003427702773795116"/>
      <mass value="0.22819516637084067"/>
      <inertia ixx="7.9e-05" ixy="2.8e-05" ixz="-1.3e-05" iyy="0.00014" iyz="5e-06" izz="0.000104"/>
    </inertial>
    <visual>
      <origin rpy="0 0 0" xyz="-0.547985 -0.25201 0.415311"/>
      <geometry>
        <mesh filename="./meshes/catch_1_1.stl" scale="0.001 0.001 0.001"/>
      </geometry>
      <material name="silver"/>
    </visual>
    <collision>
      <origin rpy="0 0 0" xyz="-0.547985 -0.25201 0.415311"/>
      <geometry>
        <mesh filename="./meshes/catch_1_1.stl" scale="0.001 0.001 0.001"/>
      </geometry>
    </collision>
  </link>
  <link name="catch_2_1">
    <inertial>
      <origin rpy="0 0 0" xyz="0.018360095385717035 0.06860801547457226 0.007749721032955903"/>
      <mass value="0.20305384054458703"/>
      <inertia ixx="7.3e-05" ixy="-2.6e-05" ixz="5e-06" iyy="0.00013" iyz="1e-06" izz="9.4e-05"/>
    </inertial>
    <visual>
      <origin rpy="0 0 0" xyz="-0.547985 -0.08201 0.415311"/>
      <geometry>
        <mesh filename="./meshes/catch_2_1.stl" scale="0.001 0.001 0.001"/>
      </geometry>
      <material name="silver"/>
    </visual>
    <collision>
      <origin rpy="0 0 0" xyz="-0.547985 -0.08201 0.415311"/>
      <geometry>
        <mesh filename="./meshes/catch_2_1.stl" scale="0.001 0.001 0.001"/>
      </geometry>
    </collision>
  </link>
  <link name="catch_1_2">
    <inertial>
      <origin rpy="0 0 0" xyz="0.016354221810908398 -0.0678905382585942 0.0034277027737359966"/>
      <mass value="0.22819516637084067"/>
      <inertia ixx="7.9e-05" ixy="2.8e-05" ixz="-1.3e-05" iyy="0.00014" iyz="5e-06" izz="0.000104"/>
    </inertial>
    <visual>
      <origin rpy="0 0 0" xyz="-0.547985 0.151994 0.415311"/>
      <geometry>
        <mesh filename="./meshes/catch_1_2.stl" scale="0.001 0.001 0.001"/>
      </geometry>
      <material name="silver"/>
    </visual>
    <collision>
      <origin rpy="0 0 0" xyz="-0.547985 0.151994 0.415311"/>
      <geometry>
        <mesh filename="./meshes/catch_1_2.stl" scale="0.001 0.001 0.001"/>
      </geometry>
    </collision>
  </link>
  <link name="catch_2_2">
    <inertial>
      <origin rpy="0 0 0" xyz="0.018360095385775987 0.0686083666179989 0.007749721032946355"/>
      <mass value="0.20305384054458703"/>
      <inertia ixx="7.3e-05" ixy="-2.6e-05" ixz="5e-06" iyy="0.00013" iyz="1e-06" izz="9.4e-05"/>
    </inertial>
    <visual>
      <origin rpy="0 0 0" xyz="-0.547985 0.321994 0.415311"/>
      <geometry>
        <mesh filename="./meshes/catch_2_2.stl" scale="0.001 0.001 0.001"/>
      </geometry>
      <material name="silver"/>
    </visual>
    <collision>
      <origin rpy="0 0 0" xyz="-0.547985 0.321994 0.415311"/>
      <geometry>
        <mesh filename="./meshes/catch_2_2.stl" scale="0.001 0.001 0.001"/>
      </geometry>
    </collision>  
  </link>
  <joint name="body_joint_1" type="prismatic">
    <origin rpy="0 0 0" xyz="-0.006085 0.035008 -0.529811"/>
    <parent link="base_link0"/>
    <child link="body_link2_1"/>
    <axis xyz="0.0 -0.0 1.0"/>
    <limit effort="100" lower="0.0" upper="0.72" velocity="100"/>
  </joint>
  <joint name="head_joint_1" type="revolute">
    <origin rpy="0 0 0" xyz="0.1805 -0.069781 -0.532"/>
    <parent link="body_link2_1"/>
    <child link="head_link1_1"/>
    <axis xyz="0.0 -0.0 1.0"/>
    <limit effort="100" lower="-1.570796" upper="1.570796" velocity="100"/>
  </joint>
  <joint name="head_joint_2" type="revolute">
    <origin rpy="0 0 0" xyz="0.0 0.025 -0.049"/>
    <parent link="head_link1_1"/>
    <child link="head_link2_1"/>
    <axis xyz="0.0 1.0 0.0"/>
    <limit effort="100" lower="-0.785398" upper="0.785398" velocity="100"/>
  </joint>
  <joint name="arm_joint_r_1" type="revolute">
    <origin rpy="0 0 0" xyz="0.1805 0.0735 -0.484"/>
    <parent link="body_link2_1"/>
    <child link="arm_r_link1_1"/>
    <axis xyz="0.0 1.0 0.0"/>
    <limit effort="100" lower="-0.523599" upper="3.141593" velocity="100"/>
  </joint>
  <joint name="arm_joint_r_2" type="revolute">
    <origin rpy="0 0 0" xyz="0.02725 0.0585 0.0"/>
    <parent link="arm_r_link1_1"/>
    <child link="arm_r_link2_1"/>
    <axis xyz="1.0 -0.0 -0.0"/>
    <limit effort="100" lower="-1.570796" upper="0.436332" velocity="100"/>
  </joint>
  <joint name="arm_joint_r_3" type="revolute">
    <origin rpy="0 0 0" xyz="-0.02725 0.0 0.0865"/>
    <parent link="arm_r_link2_1"/>
    <child link="arm_r_link3_1"/>
    <axis xyz="0.0 -0.0 1.0"/>
    <limit effort="100" lower="-1.570796" upper="1.570796" velocity="100"/>
  </joint>
  <joint name="arm_joint_r_4" type="revolute">
    <origin rpy="0 0 0" xyz="0.0 -0.02725 0.2165"/>
    <parent link="arm_r_link3_1"/>
    <child link="arm_r_link4_1"/>
    <axis xyz="0.0 1.0 0.0"/>
    <limit effort="100" lower="-1.570796" upper="0.785398" velocity="100"/>
  </joint>
  <joint name="arm_joint_r_5" type="revolute">
    <origin rpy="0 0 0" xyz="0.0935 0.02725 0.0"/>
    <parent link="arm_r_link4_1"/>
    <child link="arm_r_link5_1"/>
    <axis xyz="1.0 -0.0 -0.0"/>
    <limit effort="100" lower="-2.792527" upper="2.792527" velocity="100"/>
  </joint>
  <joint name="arm_joint_r_6" type="revolute">
    <origin rpy="0 0 0" xyz="0.0955 -0.02725 0.0"/>
    <parent link="arm_r_link5_1"/>
    <child link="arm_r_link6_1"/>
    <axis xyz="-0.0 1.0 0.0"/>
    <limit effort="100" lower="-1.570796" upper="0.785398" velocity="100"/>
  </joint>
  <joint name="arm_joint_r_7" type="revolute">
    <origin rpy="0 0 0" xyz="0.066 0.02725 0.022"/>
    <parent link="arm_r_link6_1"/>
    <child link="arm_r_link7_1"/>
    <axis xyz="0.0 -0.0 1.0"/>
    <limit effort="100" lower="-1.570796" upper="1.570796" velocity="100"/>
  </joint>
  <joint name="arm_joint_l_1" type="revolute">
    <origin rpy="0 0 0" xyz="0.1805 -0.2135 -0.484"/>
    <parent link="body_link2_1"/>
    <child link="arm_l_link1_1"/>
    <axis xyz="0.0 1.0 0.0"/>
    <limit effort="100" lower="-3.141593" upper="0.523599" velocity="100"/>
  </joint>
  <joint name="arm_joint_l_2" type="revolute">
    <origin rpy="0 0 0" xyz="0.02725 -0.0585 0.0"/>
    <parent link="arm_l_link1_1"/>
    <child link="arm_l_link2_1"/>
    <axis xyz="1.0 -0.0 -0.0"/>
    <limit effort="100" lower="-0.436332" upper="1.570796" velocity="100"/>
  </joint>
  <joint name="arm_joint_l_3" type="revolute">
    <origin rpy="0 0 0" xyz="-0.02725 0.0 0.0865"/>
    <parent link="arm_l_link2_1"/>
    <child link="arm_l_link3_1"/>
    <axis xyz="-0.0 0.0 -1.0"/>
    <limit effort="100" lower="-1.570796" upper="1.570796" velocity="100"/>
  </joint>
  <joint name="arm_joint_l_4" type="revolute">
    <origin rpy="0 0 0" xyz="0.0 0.02725 0.2165"/>
    <parent link="arm_l_link3_1"/>
    <child link="arm_l_link4_1"/>
    <axis xyz="-0.0 -1.0 -0.0"/>
    <limit effort="100" lower="-0.785398" upper="1.570796" velocity="100"/>
  </joint>
  <joint name="arm_joint_l_5" type="revolute">
    <origin rpy="0 0 0" xyz="0.0935 -0.02725 0.0"/>
    <parent link="arm_l_link4_1"/>
    <child link="arm_l_link5_1"/>
    <axis xyz="1.0 -0.0 -0.0"/>
    <limit effort="100" lower="-2.792527" upper="2.792527" velocity="100"/>
  </joint>
  <joint name="arm_joint_l_6" type="revolute">
    <origin rpy="0 0 0" xyz="0.0955 0.02725 0.0"/>
    <parent link="arm_l_link5_1"/>
    <child link="arm_l_link6_1"/>
    <axis xyz="-0.0 -1.0 -0.0"/>
    <limit effort="100" lower="-0.785398" upper="1.570796" velocity="100"/>
  </joint>
  <joint name="arm_joint_l_7" type="revolute">
    <origin rpy="0 0 0" xyz="0.066 -0.02725 0.022"/>
    <parent link="arm_l_link6_1"/>
    <child link="arm_l_link7_1"/>
    <axis xyz="-0.0 0.0 -1.0"/>
    <limit effort="100" lower="-1.570796" upper="1.570796" velocity="100"/>
  </joint>
  <joint name="wheel2" type="fixed">
    <origin rpy="0 0 0" xyz="0.175463 0.280847 -0.026811"/>
    <parent link="base_link0"/>
    <child link="wheel_2"/>
    <axis xyz="0.5 0.866025 0.0"/>
  </joint>
  <joint name="wheel1" type="fixed">
    <origin rpy="0 0 0" xyz="-0.371585 -0.034992 -0.026811"/>
    <parent link="base_link0"/>
    <child link="wheel_1"/>
    <axis xyz="-1.0 0.0 0.0"/>
  </joint>
  <joint name="wheel3" type="fixed">
    <origin rpy="0 0 0" xyz="0.175463 -0.35083 -0.026811"/>
    <parent link="base_link0"/>
    <child link="wheel_3"/>
    <axis xyz="0.5 -0.866025 -0.0"/>
  </joint>
  <joint name="catch_joint_r_1" type="prismatic">
    <origin rpy="0 0 0" xyz="0.11857 0.085002 -0.0265"/>
    <parent link="arm_r_link7_1"/>
    <child link="catch_1_1"/>
    <axis xyz="0.0 1.0 0.0"/>
    <limit effort="100" lower="-0.003172" upper="0.04765" velocity="100"/>
  </joint>
  <joint name="catch_joint_r_2" type="prismatic">
    <origin rpy="0 0 0" xyz="0.11857 -0.084998 -0.0265"/>
    <parent link="arm_r_link7_1"/>
    <child link="catch_2_1"/>
    <axis xyz="0.0 1.0 0.0"/>
    <limit effort="100" lower="-0.04765" upper="0.003172" velocity="100"/>
  </joint>
  <joint name="catch_joint_l_1" type="prismatic">
    <origin rpy="0 0 0" xyz="0.11857 0.084998 -0.0265"/>
    <parent link="arm_l_link7_1"/>
    <child link="catch_1_2"/>
    <axis xyz="0.0 -1.0 -0.0"/>
    <limit effort="100" lower="-0.04765" upper="0.003172" velocity="100"/>
  </joint>
  <joint name="catch_joint_l_2" type="prismatic">
    <origin rpy="0 0 0" xyz="0.11857 -0.085002 -0.0265"/>
    <parent link="arm_l_link7_1"/>
    <child link="catch_2_2"/>
    <axis xyz="0.0 -1.0 -0.0"/>
    <limit effort="100" lower="0.003172" upper="0.04765" velocity="100"/>
  </joint>
</robot>
